2024-06-02 23:02:56,695 - INFO - USDT Balance: 7.05619291
2024-06-02 23:02:56,695 - INFO - Insufficient USDT balance to execute trade
2024-06-02 23:02:56,696 - INFO - New coin detected: TNSR/USDT:USDT
2024-06-02 23:02:57,108 - INFO - USDT Balance: 7.05619291
2024-06-02 23:02:57,108 - INFO - Insufficient USDT balance to execute trade
2024-06-02 23:02:57,108 - INFO - New coin detected: SAGA/USDT:USDT
2024-06-02 23:02:57,485 - INFO - USDT Balance: 7.05619291
2024-06-02 23:02:57,486 - INFO - Insufficient USDT balance to execute trade
2024-06-02 23:02:57,486 - INFO - New coin detected: TAO/USDT:USDT
2024-06-02 23:02:57,837 - INFO - USDT Balance: 7.05619291
2024-06-02 23:02:57,837 - INFO - Insufficient USDT balance to execute trade
2024-06-02 23:02:57,837 - INFO - New coin detected: OMNI/USDT:USDT
2024-06-02 23:02:58,213 - INFO - USDT Balance: 7.05619291
2024-06-02 23:02:58,214 - INFO - Insufficient USDT balance to execute trade
2024-06-02 23:02:58,214 - INFO - New coin detected: REZ/USDT:USDT
2024-06-02 23:02:58,595 - INFO - USDT Balance: 7.05619291
2024-06-02 23:02:58,596 - INFO - Insufficient USDT balance to execute trade
2024-06-02 23:02:58,596 - INFO - New coin detected: BB/USDT:USDT
2024-06-02 23:02:58,946 - INFO - USDT Balance: 7.05619291
2024-06-02 23:02:58,946 - INFO - Insufficient USDT balance to execute trade
2024-06-02 23:02:58,947 - INFO - New coin detected: NOT/USDT:USDT
2024-06-02 23:02:59,321 - INFO - USDT Balance: 7.05619291
2024-06-02 23:02:59,322 - INFO - Insufficient USDT balance to execute trade
2024-06-02 23:02:59,322 - INFO - New coin detected: TURBO/USDT:USDT
2024-06-02 23:02:59,721 - INFO - USDT Balance: 7.05619291
2024-06-02 23:02:59,721 - INFO - Insufficient USDT balance to execute trade
2024-06-02 23:03:18,174 - INFO - USDT Balance: 7.05619291
Traceback (most recent call last):
  File "/home/gio/.local/lib/python3.10/site-packages/ccxt/base/exchange.py", line 645, in fetch
    response.raise_for_status()
  File "/usr/lib/python3/dist-packages/requests/models.py", line 943, in raise_for_status
    raise HTTPError(http_error_msg, response=self)
requests.exceptions.HTTPError: 400 Client Error: Bad Request for url: https://api.binance.com/api/v3/order

During handling of the above exception, another exception occurred:

Traceback (most recent call last):
  File "/home/gio/Desktop/Test/main.py", line 167, in <module>
    main()
  File "/home/gio/Desktop/Test/main.py", line 159, in main
    sell_order = place_order(symbol, 'sell', amount)
  File "/home/gio/Desktop/Test/main.py", line 59, in place_order
    order = binance.create_order(symbol, 'market', side, amount)
  File "/home/gio/.local/lib/python3.10/site-packages/ccxt/binance.py", line 5581, in create_order
    response = self.privatePostOrder(request)
  File "/home/gio/.local/lib/python3.10/site-packages/ccxt/base/types.py", line 35, in unbound_method
    return _self.request(self.path, self.api, self.method, params, config=self.config)
  File "/home/gio/.local/lib/python3.10/site-packages/ccxt/binance.py", line 10323, in request
    response = self.fetch2(path, api, method, params, headers, body, config)
  File "/home/gio/.local/lib/python3.10/site-packages/ccxt/base/exchange.py", line 3693, in fetch2
    return self.fetch(request['url'], request['method'], request['headers'], request['body'])
  File "/home/gio/.local/lib/python3.10/site-packages/ccxt/base/exchange.py", line 661, in fetch
    skip_further_error_handling = self.handle_errors(http_status_code, http_status_text, url, method, headers, http_response, json_response, request_headers, request_body)
  File "/home/gio/.local/lib/python3.10/site-packages/ccxt/binance.py", line 10267, in handle_errors
    self.throw_exactly_matched_exception(self.exceptions['exact'], message, self.id + ' ' + message)
  File "/home/gio/.local/lib/python3.10/site-packages/ccxt/base/exchange.py", line 4078, in throw_exactly_matched_exception
    raise exact[string](message)
ccxt.base.errors.MarketClosed: binance Market is closed.